<?xml version="1.0"?>
<robot name="radar_bot" xmlns:xacro="http://www.ros.org/wiki/xacro">

  <!-- Materials -->
  <material name="blue"><color rgba="0.2 0.4 0.9 1"/></material>
  <material name="black"><color rgba="0.1 0.1 0.1 1"/></material>
  <material name="red"><color rgba="0.9 0.1 0.1 1"/></material>

  <!-- Base -->
  <link name="base_footprint"/>

  <link name="base_link">
    <visual>
      <geometry><box size="0.4 0.3 0.15"/></geometry>
      <material name="blue"/>
    </visual>
    <collision>
      <geometry><box size="0.4 0.3 0.15"/></geometry>
    </collision>
    <inertial>
      <mass value="5.0"/>
      <inertia ixx="0.05" ixy="0" ixz="0" iyy="0.08" iyz="0" izz="0.1"/>
    </inertial>
  </link>

  <joint name="base_joint" type="fixed">
    <parent link="base_footprint"/>
    <child link="base_link"/>
    <origin xyz="0 0 0.1" rpy="0 0 0"/>
  </joint>

  <!-- Wheels -->
  <xacro:macro name="wheel" params="name x y">
    <link name="${name}_wheel">
      <visual>
        <origin rpy="1.5708 0 0"/>
        <geometry><cylinder radius="0.06" length="0.04"/></geometry>
        <material name="black"/>
      </visual>
      <collision>
        <origin rpy="1.5708 0 0"/>
        <geometry><cylinder radius="0.06" length="0.04"/></geometry>
      </collision>
      <inertial>
        <mass value="0.3"/>
        <inertia ixx="0.001" ixy="0" ixz="0" iyy="0.001" iyz="0" izz="0.001"/>
      </inertial>
    </link>
    <joint name="${name}_wheel_joint" type="continuous">
      <parent link="base_link"/>
      <child link="${name}_wheel"/>
      <origin xyz="${x} ${y} -0.05" rpy="0 0 0"/>
      <axis xyz="0 1 0"/>
    </joint>
  </xacro:macro>

  <xacro:wheel name="left"  x="0"  y="0.17"/>
  <xacro:wheel name="right" x="0" y="-0.17"/>

  <!-- Caster -->
  <link name="caster">
    <visual><geometry><sphere radius="0.04"/></geometry><material name="black"/></visual>
    <collision><geometry><sphere radius="0.04"/></geometry></collision>
    <inertial><mass value="0.1"/><inertia ixx="0.0001" ixy="0" ixz="0" iyy="0.0001" iyz="0" izz="0.0001"/></inertial>
  </link>
  <joint name="caster_joint" type="fixed">
    <parent link="base_link"/>
    <child link="caster"/>
    <origin xyz="0.15 0 -0.07"/>
  </joint>

  <!-- Radar link -->
  <link name="radar_link">
    <visual>
      <geometry><box size="0.06 0.08 0.03"/></geometry>
      <material name="red"/>
    </visual>
  </link>
  <joint name="radar_joint" type="fixed">
    <parent link="base_link"/>
    <child link="radar_link"/>
    <origin xyz="0.18 0 0.09" rpy="0 0 0"/>
  </joint>

  <!-- Gazebo: differential drive + radar sensor -->
  <gazebo>
    <plugin filename="gz-sim-diff-drive-system"
            name="gz::sim::systems::DiffDrive">
      <left_joint>left_wheel_joint</left_joint>
      <right_joint>right_wheel_joint</right_joint>
      <wheel_separation>0.34</wheel_separation>
      <wheel_radius>0.06</wheel_radius>
      <odom_publish_frequency>30</odom_publish_frequency>
      <topic>cmd_vel</topic>
      <odom_topic>odom</odom_topic>
      <frame_id>odom</frame_id>
      <child_frame_id>base_footprint</child_frame_id>
      <tf_topic>/tf</tf_topic>
    </plugin>

    <plugin filename="gz-sim-joint-state-publisher-system"
            name="gz::sim::systems::JointStatePublisher">
      <topic>joint_states</topic>
    </plugin>
  </gazebo>

  <gazebo reference="radar_link">
    <sensor name="radar" type="gpu_lidar">
      <pose>0 0 0 0 0 0</pose>
      <topic>radar/scan</topic>
      <update_rate>15</update_rate>
      <lidar>
        <scan>
          <horizontal>
            <samples>180</samples>
            <resolution>1</resolution>
            <min_angle>-1.57</min_angle>
            <max_angle>1.57</max_angle>
          </horizontal>
          <vertical>
            <samples>8</samples>
            <resolution>1</resolution>
            <min_angle>-0.26</min_angle>
            <max_angle>0.26</max_angle>
          </vertical>
        </scan>
        <range>
          <min>0.2</min>
          <max>25.0</max>
          <resolution>0.05</resolution>
        </range>
        <noise>
          <type>gaussian</type>
          <mean>0.0</mean>
          <stddev>0.05</stddev>
        </noise>
      </lidar>
      <always_on>1</always_on>
      <visualize>true</visualize>
    </sensor>
  </gazebo>

</robot>
